[2021-12-25 11:38:50,414] {taskinstance.py:851} INFO - Dependencies all met for <TaskInstance: data_transform.connect_minio 2021-12-25T11:38:32.119712+00:00 [queued]>
[2021-12-25 11:38:50,468] {taskinstance.py:851} INFO - Dependencies all met for <TaskInstance: data_transform.connect_minio 2021-12-25T11:38:32.119712+00:00 [queued]>
[2021-12-25 11:38:50,469] {taskinstance.py:1042} INFO - 
--------------------------------------------------------------------------------
[2021-12-25 11:38:50,471] {taskinstance.py:1043} INFO - Starting attempt 1 of 1
[2021-12-25 11:38:50,473] {taskinstance.py:1044} INFO - 
--------------------------------------------------------------------------------
[2021-12-25 11:38:50,508] {taskinstance.py:1063} INFO - Executing <Task(PythonOperator): connect_minio> on 2021-12-25T11:38:32.119712+00:00
[2021-12-25 11:38:50,521] {standard_task_runner.py:52} INFO - Started process 48 to run task
[2021-12-25 11:38:50,536] {standard_task_runner.py:76} INFO - Running: ['airflow', 'tasks', 'run', 'data_transform', 'connect_minio', '2021-12-25T11:38:32.119712+00:00', '--job-id', '192', '--pool', 'default_pool', '--raw', '--subdir', 'DAGS_FOLDER/data_transform.py', '--cfg-path', '/tmp/tmppi51zste', '--error-file', '/tmp/tmpx1wf0nk_']
[2021-12-25 11:38:50,542] {standard_task_runner.py:77} INFO - Job 192: Subtask connect_minio
[2021-12-25 11:38:50,804] {logging_mixin.py:104} INFO - Running <TaskInstance: data_transform.connect_minio 2021-12-25T11:38:32.119712+00:00 [running]> on host 9b47502ca6d8
[2021-12-25 11:38:51,036] {taskinstance.py:1257} INFO - Exporting the following env vars:
AIRFLOW_CTX_DAG_OWNER=airflow
AIRFLOW_CTX_DAG_ID=data_transform
AIRFLOW_CTX_TASK_ID=connect_minio
AIRFLOW_CTX_EXECUTION_DATE=2021-12-25T11:38:32.119712+00:00
AIRFLOW_CTX_DAG_RUN_ID=manual__2021-12-25T11:38:32.119712+00:00
[2021-12-25 11:38:51,597] {taskinstance.py:1455} ERROR - S3 operation failed; code: NoSuchBucket, message: The specified bucket does not exist, resource: /ngram, request_id: 16C3FC83A2205088, host_id: a62de7e4-724d-4dac-a324-dec86b8cdcc5, bucket_name: ngram
Traceback (most recent call last):
  File "/home/airflow/.local/lib/python3.6/site-packages/airflow/models/taskinstance.py", line 1112, in _run_raw_task
    self._prepare_and_execute_task_with_callbacks(context, task)
  File "/home/airflow/.local/lib/python3.6/site-packages/airflow/models/taskinstance.py", line 1285, in _prepare_and_execute_task_with_callbacks
    result = self._execute_task(context, task_copy)
  File "/home/airflow/.local/lib/python3.6/site-packages/airflow/models/taskinstance.py", line 1315, in _execute_task
    result = task_copy.execute(context=context)
  File "/home/airflow/.local/lib/python3.6/site-packages/airflow/operators/python.py", line 117, in execute
    return_value = self.execute_callable()
  File "/home/airflow/.local/lib/python3.6/site-packages/airflow/operators/python.py", line 128, in execute_callable
    return self.python_callable(*self.op_args, **self.op_kwargs)
  File "/opt/airflow/dags/data_transform.py", line 280, in connect_minio
    result = clientminio.fput_object(bucket_name, predict_label+"/"+lst, os.path.join(process_dir,filename))
  File "/usr/local/lib/python3.6/site-packages/minio/api.py", line 988, in fput_object
    tags=tags, retention=retention, legal_hold=legal_hold,
  File "/usr/local/lib/python3.6/site-packages/minio/api.py", line 1758, in put_object
    raise exc
  File "/usr/local/lib/python3.6/site-packages/minio/api.py", line 1713, in put_object
    bucket_name, object_name, part_data, headers,
  File "/usr/local/lib/python3.6/site-packages/minio/api.py", line 1577, in _put_object
    no_body_trace=True,
  File "/usr/local/lib/python3.6/site-packages/minio/api.py", line 394, in _execute
    region = self._get_region(bucket_name, None)
  File "/usr/local/lib/python3.6/site-packages/minio/api.py", line 465, in _get_region
    query_params={"location": ""},
  File "/usr/local/lib/python3.6/site-packages/minio/api.py", line 380, in _url_open
    raise response_error
minio.error.S3Error: S3 operation failed; code: NoSuchBucket, message: The specified bucket does not exist, resource: /ngram, request_id: 16C3FC83A2205088, host_id: a62de7e4-724d-4dac-a324-dec86b8cdcc5, bucket_name: ngram
[2021-12-25 11:38:51,607] {taskinstance.py:1503} INFO - Marking task as FAILED. dag_id=data_transform, task_id=connect_minio, execution_date=20211225T113832, start_date=20211225T113850, end_date=20211225T113851
[2021-12-25 11:38:51,773] {local_task_job.py:146} INFO - Task exited with return code 1
